Workbook

Sheet Tableau de bord
A1: Tableau de bord — progression
A2: Se met à jour automatiquement quand vous changez les statuts dans la feuille Suivi_Vienne.
A4: Département | B4: Vienne (86)
A5: Communes au total | B5: =COUNTA(Suivi_Vienne!$A$5:$A$269) -> 265
A6: Visité | B6: =COUNTIF(Suivi_Vienne!$C$5:$C$269,"Visité") -> 3
A7: Prévu | B7: =COUNTIF(Suivi_Vienne!$C$5:$C$269,"Prévu") -> 2
A8: À visiter | B8: =COUNTIF(Suivi_Vienne!$C$5:$C$269,"À visiter") -> 260
A9: % visité | B9: =IFERROR(B6/B5,0) -> 0.011320755

Sheet Référentiel
A1: Référentiel des communes de France
A2: Source : Etalab / INSEE — Code Officiel Géographique, millésime 2026 (@etalab/decoupage-administratif v6.0.0). Clé unique : code INSEE. Feuille figée — ne pas modifier.
A4: code_INSEE | B4: nom | C4: departement | D4: nom_departement | E4: region | F4: nom_region | G4: population
A5: 01006 | B5: Ambléon | C5: 01 | D5: Ain | E5: 84 | F5: Auvergne-Rhône-Alpes | G5: 115
A6: 01007 | B6: Ambronay | C6: 01 | D6: Ain | E6: 84 | F6: Auvergne-Rhône-Alpes | G6: 2841
A7: 01008 | B7: Ambutrix | C7: 01 | D7: Ain | E7: 84 | F7: Auvergne-Rhône-Alpes | G7: 760
A8: 01004 | B8: Ambérieu-en-Bugey | C8: 01 | D8: Ain | E8: 84 | F8: Auvergne-Rhône-Alpes | G8: 15934
A9: 01005 | B9: Ambérieux-en-Dombes | C9: 01 | D9: Ain | E9: 84 | F9: Auvergne-Rhône-Alpes | G9: 1906
A10: 01009 | B10: Andert-et-Condon | C10: 01 | D10: Ain | E10: 84 | F10: Auvergne-Rhône-Alpes | G10: 348
A11: 01010 | B11: Anglefort | C11: 01 | D11: Ain | E11: 84 | F11: Auvergne-Rhône-Alpes | G11: 1174
A12: 01011 | B12: Apremont | C12: 01 | D12: Ain | E12: 84 | F12: Auvergne-Rhône-Alpes | G12: 415
A13: 01012 | B13: Aranc | C13: 01 | D13: Ain | E13: 84 | F13: Auvergne-Rhône-Alpes | G13: 331
A14: 01013 | B14: Arandas | C14: 01 | D14: Ain | E14: 84 | F14: Auvergne-Rhône-Alpes | G14: 138
A15: 01014 | B15: Arbent | C15: 01 | D15: Ain | E15: 84 | F15: Auvergne-Rhône-Alpes | G15: 3555
A16: 01016 | B16: Arbigny | C16: 01 | D16: Ain | E16: 84 | F16: Auvergne-Rhône-Alpes | G16: 462
... A34883: 97801 | B34883: Saint-Martin | C34883: 978 | D34883: Saint-Martin | E34883: 978 | F34883: Saint-Martin | G34883: 31160
A34884: 98413 | B34884: Archipel des Crozet | C34884: 984 | D34884: Terres australes et antarctiques françaises | E34884: 984 | F34884: Terres australes et antarctiques françaises
A34885: 98412 | B34885: Archipel des Kerguelen | C34885: 984 | D34885: Terres australes et antarctiques françaises | E34885: 984 | F34885: Terres australes et antarctiques françaises
A34886: 98414 | B34886: La Terre-Adélie | C34886: 984 | D34886: Terres australes et antarctiques françaises | E34886: 984 | F34886: Terres australes et antarctiques françaises
A34887: 98411 | B34887: Îles Saint-Paul et Nouvelle-Amsterdam | C34887: 984 | D34887: Terres australes et antarctiques françaises | E34887: 984 | F34887: Terres australes et antarctiques françaises
A34888: 98415 | B34888: Îles Éparses de l'océan Indien | C34888: 984 | D34888: Terres australes et antarctiques françaises | E34888: 984 | F34888: Terres australes et antarctiques françaises
A34889: 98611 | B34889: Alo | C34889: 986 | D34889: Wallis et Futuna | E34889: 986 | F34889: Wallis et Futuna | G34889: 1875
A34890: 98612 | B34890: Sigave | C34890: 986 | D34890: Wallis et Futuna | E34890: 986 | F34890: Wallis et Futuna | G34890: 1188
A34891: 98613 | B34891: Uvea | C34891: 986 | D34891: Wallis et Futuna | E34891: 986 | F34891: Wallis et Futuna | G34891: 8088
A34892: 98711 | B34892: Anaa | C34892: 987 | D34892: Polynésie française | E34892: 987 | F34892: Polynésie française | G34892: 970
A34893: 98712 | B34893: Arue | C34893: 987 | D34893: Polynésie française | E34893: 987 | F34893: Polynésie française | G34893: 10322
A34894: 98713 | B34894: Arutua | C34894: 987 | D34894: Polynésie française | E34894: 987 | F34894: Polynésie française | G34894: 1736
A34895: 98714 | B34895: Bora-Bora | C34895: 987 | D34895: Polynésie française | E34895: 987 | F34895: Polynésie française | G34895: 10758
A34896: 98715 | B34896: Faaa | C34896: 987 | D34896: Polynésie française | E34896: 987 | F34896: Polynésie française | G34896: 29826
A34897: 98716 | B34897: Fakarava | C34897: 987 | D34897: Polynésie française | E34897: 987 | F34897: Polynésie française | G34897: 1679
A34898: 98717 | B34898: Fangatau | C34898: 987 | D34898: Polynésie française | E34898: 987 | F34898: Polynésie française | G34898: 323
A34899: 98718 | B34899: Fatu-Hiva | C34899: 987 | D34899: Polynésie française | E34899: 987 | F34899: Polynésie française | G34899: 600
A34900: 98719 | B34900: Gambier | C34900: 987 | D34900: Polynésie française | E34900: 987 | F34900: Polynésie française | G34900: 1570
... A34972: 98832 | B34972: Yaté | C34972: 988 | D34972: Nouvelle-Calédonie | E34972: 988 | F34972: Nouvelle-Calédonie | G34972: 1588
A34973: 98901 | B34973: Île de Clipperton | C34973: 989 | D34973: Île de Clipperton | E34973: 989 | F34973: Île de Clipperton

Sheet Suivi_Vienne
A1: Suivi des visites — Vienne (86)
A2: Zone de travail. Saisir uniquement les colonnes Statut, Date et Notes (fond crème). Le nom se remplit tout seul depuis le Référentiel via le code INSEE.
A4: code_INSEE | B4: nom (auto) | C4: statut | D4: date_visite | E4: notes
A5: 86001 | B5: =IFERROR(INDEX(Référentiel!$B$5:$B$34973,MATCH(A5,Référentiel!$A$5:$A$34973,0)),"code inconnu") -> Adriers | C5: À visiter
A6: 86002 | B6: =IFERROR(INDEX(Référentiel!$B$5:$B$34973,MATCH(A6,Référentiel!$A$5:$A$34973,0)),"code inconnu") -> Amberre | C6: À visiter
A7: 86003 | B7: =IFERROR(INDEX(Référentiel!$B$5:$B$34973,MATCH(A7,Référentiel!$A$5:$A$34973,0)),"code inconnu") -> Anché | C7: À visiter
A8: 86004 | B8: =IFERROR(INDEX(Référentiel!$B$5:$B$34973,MATCH(A8,Référentiel!$A$5:$A$34973,0)),"code inconnu") -> Angles-sur-l'Anglin | C8: À visiter
A9: 86005 | B9: =IFERROR(INDEX(Référentiel!$B$5:$B$34973,MATCH(A9,Référentiel!$A$5:$A$34973,0)),"code inconnu") -> Angliers | C9: À visiter
A10: 86006 | B10: =IFERROR(INDEX(Référentiel!$B$5:$B$34973,MATCH(A10,Référentiel!$A$5:$A$34973,0)),"code inconnu") -> Antigny | C10: À visiter
A11: 86007 | B11: =IFERROR(INDEX(Référentiel!$B$5:$B$34973,MATCH(A11,Référentiel!$A$5:$A$34973,0)),"code inconnu") -> Antran | C11: À visiter
A12: 86009 | B12: =IFERROR(INDEX(Référentiel!$B$5:$B$34973,MATCH(A12,Référentiel!$A$5:$A$34973,0)),"code inconnu") -> Archigny | C12: À visiter
A13: 86008 | B13: =IFERROR(INDEX(Référentiel!$B$5:$B$34973,MATCH(A13,Référentiel!$A$5:$A$34973,0)),"code inconnu") -> Arçay | C13: À visiter
A14: 86010 | B14: =IFERROR(INDEX(Référentiel!$B$5:$B$34973,MATCH(A14,Référentiel!$A$5:$A$34973,0)),"code inconnu") -> Aslonnes | C14: À visiter
A15: 86011 | B15: =IFERROR(INDEX(Référentiel!$B$5:$B$34973,MATCH(A15,Référentiel!$A$5:$A$34973,0)),"code inconnu") -> Asnières-sur-Blour | C15: À visiter
A16: 86012 | B16: =IFERROR(INDEX(Référentiel!$B$5:$B$34973,MATCH(A16,Référentiel!$A$5:$A$34973,0)),"code inconnu") -> Asnois | C16: À visiter
... A39: 86039 | B39: =IFERROR(INDEX(Référentiel!$B$5:$B$34973,MATCH(A39,Référentiel!$A$5:$A$34973,0)),"code inconnu") -> Brux | C39: À visiter
A40: 86041 | B40: =IFERROR(INDEX(Référentiel!$B$5:$B$34973,MATCH(A40,Référentiel!$A$5:$A$34973,0)),"code inconnu") -> Buxerolles | C40: Visité | D40: 2026-05-10
A41: 86042 | B41: =IFERROR(INDEX(Référentiel!$B$5:$B$34973,MATCH(A41,Référentiel!$A$5:$A$34973,0)),"code inconnu") -> Buxeuil | C41: À visiter
A42: 86024 | B42: =IFERROR(INDEX(Référentiel!$B$5:$B$34973,MATCH(A42,Référentiel!$A$5:$A$34973,0)),"code inconnu") -> Béruges | C42: À visiter
A43: 86025 | B43: =IFERROR(INDEX(Référentiel!$B$5:$B$34973,MATCH(A43,Référentiel!$A$5:$A$34973,0)),"code inconnu") -> Béthines | C43: À visiter
A44: 86044 | B44: =IFERROR(INDEX(Référentiel!$B$5:$B$34973,MATCH(A44,Référentiel!$A$5:$A$34973,0)),"code inconnu") -> Ceaux-en-Loudun | C44: À visiter
A45: 86045 | B45: =IFERROR(INDEX(Référentiel!$B$5:$B$34973,MATCH(A45,Référentiel!$A$5:$A$34973,0)),"code inconnu") -> Celle-Lévescault | C45: À visiter
A46: 86046 | B46: =IFERROR(INDEX(Référentiel!$B$5:$B$34973,MATCH(A46,Référentiel!$A$5:$A$34973,0)),"code inconnu") -> Cenon-sur-Vienne | C46: À visiter
A47: 86047 | B47: =IFERROR(INDEX(Référentiel!$B$5:$B$34973,MATCH(A47,Référentiel!$A$5:$A$34973,0)),"code inconnu") -> Cernay | C47: À visiter
A48: 86048 | B48: =IFERROR(INDEX(Référentiel!$B$5:$B$34973,MATCH(A48,Référentiel!$A$5:$A$34973,0)),"code inconnu") -> Chabournay | C48: À visiter
A49: 86049 | B49: =IFERROR(INDEX(Référentiel!$B$5:$B$34973,MATCH(A49,Référentiel!$A$5:$A$34973,0)),"code inconnu") -> Chalais | C49: À visiter
A50: 86050 | B50: =IFERROR(INDEX(Référentiel!$B$5:$B$34973,MATCH(A50,Référentiel!$A$5:$A$34973,0)),"code inconnu") -> Chalandray | C50: À visiter
A51: 86052 | B51: =IFERROR(INDEX(Référentiel!$B$5:$B$34973,MATCH(A51,Référentiel!$A$5:$A$34973,0)),"code inconnu") -> Champagné-Saint-Hilaire | C51: À visiter
A52: 86051 | B52: =IFERROR(INDEX(Référentiel!$B$5:$B$34973,MATCH(A52,Référentiel!$A$5:$A$34973,0)),"code inconnu") -> Champagné-le-Sec | C52: À visiter
... A185: 86193 | B185: =IFERROR(INDEX(Référentiel!$B$5:$B$34973,MATCH(A185,Référentiel!$A$5:$A$34973,0)),"code inconnu") -> Pleumartin | C185: À visiter
A186: 86194 | B186: =IFERROR(INDEX(Référentiel!$B$5:$B$34973,MATCH(A186,Référentiel!$A$5:$A$34973,0)),"code inconnu") -> Poitiers | C186: Visité | D186: 2026-05-10 | E186: Centre historique, Notre-Dame-la-Grande
A187: 86195 | B187: =IFERROR(INDEX(Référentiel!$B$5:$B$34973,MATCH(A187,Référentiel!$A$5:$A$34973,0)),"code inconnu") -> Port-de-Piles | C187: À visiter
A188: 86197 | B188: =IFERROR(INDEX(Référentiel!$B$5:$B$34973,MATCH(A188,Référentiel!$A$5:$A$34973,0)),"code inconnu") -> Pouant | C188: À visiter
A189: 86196 | B189: =IFERROR(INDEX(Référentiel!$B$5:$B$34973,MATCH(A189,Référentiel!$A$5:$A$34973,0)),"code inconnu") -> Pouançay | C189: À visiter
A190: 86198 | B190: =IFERROR(INDEX(Référentiel!$B$5:$B$34973,MATCH(A190,Référentiel!$A$5:$A$34973,0)),"code inconnu") -> Pouillé | C190: À visiter
A191: 86200 | B191: =IFERROR(INDEX(Référentiel!$B$5:$B$34973,MATCH(A191,Référentiel!$A$5:$A$34973,0)),"code inconnu") -> Pressac | C191: À visiter
A192: 86201 | B192: =IFERROR(INDEX(Référentiel!$B$5:$B$34973,MATCH(A192,Référentiel!$A$5:$A$34973,0)),"code inconnu") -> Prinçay | C192: À visiter
A193: 86203 | B193: =IFERROR(INDEX(Référentiel!$B$5:$B$34973,MATCH(A193,Référentiel!$A$5:$A$34973,0)),"code inconnu") -> Queaux | C193: À visiter
A194: 86204 | B194: =IFERROR(INDEX(Référentiel!$B$5:$B$34973,MATCH(A194,Référentiel!$A$5:$A$34973,0)),"code inconnu") -> Quinçay | C194: À visiter
A195: 86205 | B195: =IFERROR(INDEX(Référentiel!$B$5:$B$34973,MATCH(A195,Référentiel!$A$5:$A$34973,0)),"code inconnu") -> Ranton | C195: À visiter
...
